F:\ccg\model\EffectHelperModel.py modified; restarting server
error closing fd 224
Traceback (most recent call last):
  File "C:\Python27\lib\site-packages\tornado-3.1.1-py2.7.egg\tornado\ioloop.py", line 519, in close
    os.close(fd)
OSError: [Errno 9] Bad file descriptor
error closing fd 660
Traceback (most recent call last):
  File "C:\Python27\lib\site-packages\tornado-3.1.1-py2.7.egg\tornado\ioloop.py", line 519, in close
    os.close(fd)
OSError: [Errno 9] Bad file descriptor
error closing fd 672
Traceback (most recent call last):
  File "C:\Python27\lib\site-packages\tornado-3.1.1-py2.7.egg\tornado\ioloop.py", line 519, in close
    os.close(fd)
OSError: [Errno 9] Bad file descriptor
error closing fd 156
Traceback (most recent call last):
  File "C:\Python27\lib\site-packages\tornado-3.1.1-py2.7.egg\tornado\ioloop.py", line 519, in close
    os.close(fd)
OSError: [Errno 9] Bad file descriptor
Uncaught exception, closing connection.
Traceback (most recent call last):
  File "C:\Python27\lib\site-packages\tornado-3.1.1-py2.7.egg\tornado\iostream.py", line 341, in wrapper
    callback(*args)
  File "C:\Python27\lib\site-packages\tornado-3.1.1-py2.7.egg\tornado\stack_context.py", line 331, in wrapped
    raise_exc_info(exc)
  File "C:\Python27\lib\site-packages\tornado-3.1.1-py2.7.egg\tornado\stack_context.py", line 302, in wrapped
    ret = fn(*args, **kwargs)
  File "server.py", line 179, in send_message
    res= self.parse_message(data)
  File "server.py", line 149, in parse_message
    data, push_data= func(params)
  File "F:\ccg\service\FightService.py", line 1222, in UseSkillCard
    SkillModel.triggerEffects(room, effects, 2, target)
  File "./model\SkillModel.py", line 119, in triggerEffects
    self.doEffect(room, pos, effect, uniqids)
  File "./model\SkillModel.py", line 147, in doEffect
    return 	EffectModel.doEffectArmor(room, pos, effect, uniqids)
  File "F:\ccg\model\EffectModel.py", line 236, in doEffectArmor
    k, k2= EffectHelperModel.getEffectPointer(pointer, range)
  File "F:\ccg\model\EffectHelperModel.py", line 158, in getEffectPointer
    if pos== 1:
NameError: global name 'pos' is not defined
Exception in callback <functools.partial object at 0x029EC690>
Traceback (most recent call last):
  File "C:\Python27\lib\site-packages\tornado-3.1.1-py2.7.egg\tornado\ioloop.py", line 458, in _run_callback
    callback()
  File "C:\Python27\lib\site-packages\tornado-3.1.1-py2.7.egg\tornado\stack_context.py", line 331, in wrapped
    raise_exc_info(exc)
  File "C:\Python27\lib\site-packages\tornado-3.1.1-py2.7.egg\tornado\stack_context.py", line 302, in wrapped
    ret = fn(*args, **kwargs)
  File "C:\Python27\lib\site-packages\tornado-3.1.1-py2.7.egg\tornado\iostream.py", line 341, in wrapper
    callback(*args)
  File "C:\Python27\lib\site-packages\tornado-3.1.1-py2.7.egg\tornado\stack_context.py", line 331, in wrapped
    raise_exc_info(exc)
  File "C:\Python27\lib\site-packages\tornado-3.1.1-py2.7.egg\tornado\stack_context.py", line 302, in wrapped
    ret = fn(*args, **kwargs)
  File "server.py", line 179, in send_message
    res= self.parse_message(data)
  File "server.py", line 149, in parse_message
    data, push_data= func(params)
  File "F:\ccg\service\FightService.py", line 1222, in UseSkillCard
    SkillModel.triggerEffects(room, effects, 2, target)
  File "./model\SkillModel.py", line 119, in triggerEffects
    self.doEffect(room, pos, effect, uniqids)
  File "./model\SkillModel.py", line 147, in doEffect
    return 	EffectModel.doEffectArmor(room, pos, effect, uniqids)
  File "F:\ccg\model\EffectModel.py", line 236, in doEffectArmor
    k, k2= EffectHelperModel.getEffectPointer(pointer, range)
  File "F:\ccg\model\EffectHelperModel.py", line 158, in getEffectPointer
    if pos== 1:
NameError: global name 'pos' is not defined
Uncaught exception, closing connection.
Traceback (most recent call last):
  File "C:\Python27\lib\site-packages\tornado-3.1.1-py2.7.egg\tornado\iostream.py", line 341, in wrapper
    callback(*args)
  File "C:\Python27\lib\site-packages\tornado-3.1.1-py2.7.egg\tornado\stack_context.py", line 331, in wrapped
    raise_exc_info(exc)
  File "C:\Python27\lib\site-packages\tornado-3.1.1-py2.7.egg\tornado\stack_context.py", line 302, in wrapped
    ret = fn(*args, **kwargs)
  File "server.py", line 179, in send_message
    res= self.parse_message(data)
  File "server.py", line 149, in parse_message
    data, push_data= func(params)
  File "F:\ccg\service\FightService.py", line 1152, in UseSkillCard
    SkillModel.triggerEffects(room, effects, 1, target)
  File "./model\SkillModel.py", line 119, in triggerEffects
    self.doEffect(room, pos, effect, uniqids)
  File "./model\SkillModel.py", line 147, in doEffect
    return 	EffectModel.doEffectArmor(room, pos, effect, uniqids)
  File "F:\ccg\model\EffectModel.py", line 236, in doEffectArmor
    k, k2= EffectHelperModel.getEffectPointer(pointer, range)
  File "F:\ccg\model\EffectHelperModel.py", line 158, in getEffectPointer
    if pos== 1:
NameError: global name 'pos' is not defined
Exception in callback <functools.partial object at 0x02AAEE10>
Traceback (most recent call last):
  File "C:\Python27\lib\site-packages\tornado-3.1.1-py2.7.egg\tornado\ioloop.py", line 458, in _run_callback
    callback()
  File "C:\Python27\lib\site-packages\tornado-3.1.1-py2.7.egg\tornado\stack_context.py", line 331, in wrapped
    raise_exc_info(exc)
  File "C:\Python27\lib\site-packages\tornado-3.1.1-py2.7.egg\tornado\stack_context.py", line 302, in wrapped
    ret = fn(*args, **kwargs)
  File "C:\Python27\lib\site-packages\tornado-3.1.1-py2.7.egg\tornado\iostream.py", line 341, in wrapper
    callback(*args)
  File "C:\Python27\lib\site-packages\tornado-3.1.1-py2.7.egg\tornado\stack_context.py", line 331, in wrapped
    raise_exc_info(exc)
  File "C:\Python27\lib\site-packages\tornado-3.1.1-py2.7.egg\tornado\stack_context.py", line 302, in wrapped
    ret = fn(*args, **kwargs)
  File "server.py", line 179, in send_message
    res= self.parse_message(data)
  File "server.py", line 149, in parse_message
    data, push_data= func(params)
  File "F:\ccg\service\FightService.py", line 1152, in UseSkillCard
    SkillModel.triggerEffects(room, effects, 1, target)
  File "./model\SkillModel.py", line 119, in triggerEffects
    self.doEffect(room, pos, effect, uniqids)
  File "./model\SkillModel.py", line 147, in doEffect
    return 	EffectModel.doEffectArmor(room, pos, effect, uniqids)
  File "F:\ccg\model\EffectModel.py", line 236, in doEffectArmor
    k, k2= EffectHelperModel.getEffectPointer(pointer, range)
  File "F:\ccg\model\EffectHelperModel.py", line 158, in getEffectPointer
    if pos== 1:
NameError: global name 'pos' is not defined
F:\ccg\model\EffectHelperModel.py modified; restarting server
error closing fd 224
Traceback (most recent call last):
  File "C:\Python27\lib\site-packages\tornado-3.1.1-py2.7.egg\tornado\ioloop.py", line 519, in close
    os.close(fd)
OSError: [Errno 9] Bad file descriptor
error closing fd 156
Traceback (most recent call last):
  File "C:\Python27\lib\site-packages\tornado-3.1.1-py2.7.egg\tornado\ioloop.py", line 519, in close
    os.close(fd)
OSError: [Errno 9] Bad file descriptor
F:\ccg\model\EffectModel.py modified; restarting server
error closing fd 224
Traceback (most recent call last):
  File "C:\Python27\lib\site-packages\tornado-3.1.1-py2.7.egg\tornado\ioloop.py", line 519, in close
    os.close(fd)
OSError: [Errno 9] Bad file descriptor
error closing fd 156
Traceback (most recent call last):
  File "C:\Python27\lib\site-packages\tornado-3.1.1-py2.7.egg\tornado\ioloop.py", line 519, in close
    os.close(fd)
OSError: [Errno 9] Bad file descriptor
F:\ccg\model\EffectModel.py modified; restarting server
error closing fd 224
Traceback (most recent call last):
  File "C:\Python27\lib\site-packages\tornado-3.1.1-py2.7.egg\tornado\ioloop.py", line 519, in close
    os.close(fd)
OSError: [Errno 9] Bad file descriptor
error closing fd 156
Traceback (most recent call last):
  File "C:\Python27\lib\site-packages\tornado-3.1.1-py2.7.egg\tornado\ioloop.py", line 519, in close
    os.close(fd)
OSError: [Errno 9] Bad file descriptor
F:\ccg\model\EffectModel.py modified; restarting server
error closing fd 224
Traceback (most recent call last):
  File "C:\Python27\lib\site-packages\tornado-3.1.1-py2.7.egg\tornado\ioloop.py", line 519, in close
    os.close(fd)
OSError: [Errno 9] Bad file descriptor
error closing fd 156
Traceback (most recent call last):
  File "C:\Python27\lib\site-packages\tornado-3.1.1-py2.7.egg\tornado\ioloop.py", line 519, in close
    os.close(fd)
OSError: [Errno 9] Bad file descriptor
F:\ccg\model\EffectModel.py modified; restarting server
error closing fd 224
Traceback (most recent call last):
  File "C:\Python27\lib\site-packages\tornado-3.1.1-py2.7.egg\tornado\ioloop.py", line 519, in close
    os.close(fd)
OSError: [Errno 9] Bad file descriptor
error closing fd 156
Traceback (most recent call last):
  File "C:\Python27\lib\site-packages\tornado-3.1.1-py2.7.egg\tornado\ioloop.py", line 519, in close
    os.close(fd)
OSError: [Errno 9] Bad file descriptor
F:\ccg\model\EffectModel.py modified; restarting server
error closing fd 224
Traceback (most recent call last):
  File "C:\Python27\lib\site-packages\tornado-3.1.1-py2.7.egg\tornado\ioloop.py", line 519, in close
    os.close(fd)
OSError: [Errno 9] Bad file descriptor
error closing fd 156
Traceback (most recent call last):
  File "C:\Python27\lib\site-packages\tornado-3.1.1-py2.7.egg\tornado\ioloop.py", line 519, in close
    os.close(fd)
OSError: [Errno 9] Bad file descriptor
F:\ccg\model\EffectModel.py modified; restarting server
error closing fd 224
Traceback (most recent call last):
  File "C:\Python27\lib\site-packages\tornado-3.1.1-py2.7.egg\tornado\ioloop.py", line 519, in close
    os.close(fd)
OSError: [Errno 9] Bad file descriptor
error closing fd 156
Traceback (most recent call last):
  File "C:\Python27\lib\site-packages\tornado-3.1.1-py2.7.egg\tornado\ioloop.py", line 519, in close
    os.close(fd)
OSError: [Errno 9] Bad file descriptor
F:\ccg\model\EffectModel.py modified; restarting server
error closing fd 224
Traceback (most recent call last):
  File "C:\Python27\lib\site-packages\tornado-3.1.1-py2.7.egg\tornado\ioloop.py", line 519, in close
    os.close(fd)
OSError: [Errno 9] Bad file descriptor
error closing fd 156
Traceback (most recent call last):
  File "C:\Python27\lib\site-packages\tornado-3.1.1-py2.7.egg\tornado\ioloop.py", line 519, in close
    os.close(fd)
OSError: [Errno 9] Bad file descriptor
F:\ccg\model\EffectHelperModel.py modified; restarting server
error closing fd 224
Traceback (most recent call last):
  File "C:\Python27\lib\site-packages\tornado-3.1.1-py2.7.egg\tornado\ioloop.py", line 519, in close
    os.close(fd)
OSError: [Errno 9] Bad file descriptor
error closing fd 156
Traceback (most recent call last):
  File "C:\Python27\lib\site-packages\tornado-3.1.1-py2.7.egg\tornado\ioloop.py", line 519, in close
    os.close(fd)
OSError: [Errno 9] Bad file descriptor
F:\ccg\const.py modified; restarting server
error closing fd 224
Traceback (most recent call last):
  File "C:\Python27\lib\site-packages\tornado-3.1.1-py2.7.egg\tornado\ioloop.py", line 519, in close
    os.close(fd)
OSError: [Errno 9] Bad file descriptor
error closing fd 660
Traceback (most recent call last):
  File "C:\Python27\lib\site-packages\tornado-3.1.1-py2.7.egg\tornado\ioloop.py", line 519, in close
    os.close(fd)
OSError: [Errno 9] Bad file descriptor
error closing fd 664
Traceback (most recent call last):
  File "C:\Python27\lib\site-packages\tornado-3.1.1-py2.7.egg\tornado\ioloop.py", line 519, in close
    os.close(fd)
OSError: [Errno 9] Bad file descriptor
error closing fd 156
Traceback (most recent call last):
  File "C:\Python27\lib\site-packages\tornado-3.1.1-py2.7.egg\tornado\ioloop.py", line 519, in close
    os.close(fd)
OSError: [Errno 9] Bad file descriptor
F:\ccg\const.py modified; restarting server
error closing fd 224
Traceback (most recent call last):
  File "C:\Python27\lib\site-packages\tornado-3.1.1-py2.7.egg\tornado\ioloop.py", line 519, in close
    os.close(fd)
OSError: [Errno 9] Bad file descriptor
error closing fd 156
Traceback (most recent call last):
  File "C:\Python27\lib\site-packages\tornado-3.1.1-py2.7.egg\tornado\ioloop.py", line 519, in close
    os.close(fd)
OSError: [Errno 9] Bad file descriptor
F:\ccg\const.py modified; restarting server
error closing fd 224
Traceback (most recent call last):
  File "C:\Python27\lib\site-packages\tornado-3.1.1-py2.7.egg\tornado\ioloop.py", line 519, in close
    os.close(fd)
OSError: [Errno 9] Bad file descriptor
error closing fd 156
Traceback (most recent call last):
  File "C:\Python27\lib\site-packages\tornado-3.1.1-py2.7.egg\tornado\ioloop.py", line 519, in close
    os.close(fd)
OSError: [Errno 9] Bad file descriptor
F:\ccg\const.py modified; restarting server
error closing fd 224
Traceback (most recent call last):
  File "C:\Python27\lib\site-packages\tornado-3.1.1-py2.7.egg\tornado\ioloop.py", line 519, in close
    os.close(fd)
OSError: [Errno 9] Bad file descriptor
error closing fd 156
Traceback (most recent call last):
  File "C:\Python27\lib\site-packages\tornado-3.1.1-py2.7.egg\tornado\ioloop.py", line 519, in close
    os.close(fd)
OSError: [Errno 9] Bad file descriptor
F:\ccg\const.py modified; restarting server
error closing fd 224
Traceback (most recent call last):
  File "C:\Python27\lib\site-packages\tornado-3.1.1-py2.7.egg\tornado\ioloop.py", line 519, in close
    os.close(fd)
OSError: [Errno 9] Bad file descriptor
error closing fd 156
Traceback (most recent call last):
  File "C:\Python27\lib\site-packages\tornado-3.1.1-py2.7.egg\tornado\ioloop.py", line 519, in close
    os.close(fd)
OSError: [Errno 9] Bad file descriptor
F:\ccg\const.py modified; restarting server
error closing fd 224
Traceback (most recent call last):
  File "C:\Python27\lib\site-packages\tornado-3.1.1-py2.7.egg\tornado\ioloop.py", line 519, in close
    os.close(fd)
OSError: [Errno 9] Bad file descriptor
error closing fd 156
Traceback (most recent call last):
  File "C:\Python27\lib\site-packages\tornado-3.1.1-py2.7.egg\tornado\ioloop.py", line 519, in close
    os.close(fd)
OSError: [Errno 9] Bad file descriptor
F:\ccg\const.py modified; restarting server
error closing fd 224
Traceback (most recent call last):
  File "C:\Python27\lib\site-packages\tornado-3.1.1-py2.7.egg\tornado\ioloop.py", line 519, in close
    os.close(fd)
OSError: [Errno 9] Bad file descriptor
error closing fd 156
Traceback (most recent call last):
  File "C:\Python27\lib\site-packages\tornado-3.1.1-py2.7.egg\tornado\ioloop.py", line 519, in close
    os.close(fd)
OSError: [Errno 9] Bad file descriptor
F:\ccg\const.py modified; restarting server
error closing fd 224
Traceback (most recent call last):
  File "C:\Python27\lib\site-packages\tornado-3.1.1-py2.7.egg\tornado\ioloop.py", line 519, in close
    os.close(fd)
OSError: [Errno 9] Bad file descriptor
error closing fd 156
Traceback (most recent call last):
  File "C:\Python27\lib\site-packages\tornado-3.1.1-py2.7.egg\tornado\ioloop.py", line 519, in close
    os.close(fd)
OSError: [Errno 9] Bad file descriptor
F:\ccg\const.py modified; restarting server
error closing fd 224
Traceback (most recent call last):
  File "C:\Python27\lib\site-packages\tornado-3.1.1-py2.7.egg\tornado\ioloop.py", line 519, in close
    os.close(fd)
OSError: [Errno 9] Bad file descriptor
error closing fd 156
Traceback (most recent call last):
  File "C:\Python27\lib\site-packages\tornado-3.1.1-py2.7.egg\tornado\ioloop.py", line 519, in close
    os.close(fd)
OSError: [Errno 9] Bad file descriptor
F:\ccg\const.py modified; restarting server
error closing fd 224
Traceback (most recent call last):
  File "C:\Python27\lib\site-packages\tornado-3.1.1-py2.7.egg\tornado\ioloop.py", line 519, in close
    os.close(fd)
OSError: [Errno 9] Bad file descriptor
error closing fd 156
Traceback (most recent call last):
  File "C:\Python27\lib\site-packages\tornado-3.1.1-py2.7.egg\tornado\ioloop.py", line 519, in close
    os.close(fd)
OSError: [Errno 9] Bad file descriptor
F:\ccg\const.py modified; restarting server
error closing fd 224
Traceback (most recent call last):
  File "C:\Python27\lib\site-packages\tornado-3.1.1-py2.7.egg\tornado\ioloop.py", line 519, in close
    os.close(fd)
OSError: [Errno 9] Bad file descriptor
error closing fd 156
Traceback (most recent call last):
  File "C:\Python27\lib\site-packages\tornado-3.1.1-py2.7.egg\tornado\ioloop.py", line 519, in close
    os.close(fd)
OSError: [Errno 9] Bad file descriptor
F:\ccg\const.py modified; restarting server
error closing fd 224
Traceback (most recent call last):
  File "C:\Python27\lib\site-packages\tornado-3.1.1-py2.7.egg\tornado\ioloop.py", line 519, in close
    os.close(fd)
OSError: [Errno 9] Bad file descriptor
error closing fd 156
Traceback (most recent call last):
  File "C:\Python27\lib\site-packages\tornado-3.1.1-py2.7.egg\tornado\ioloop.py", line 519, in close
    os.close(fd)
OSError: [Errno 9] Bad file descriptor
F:\ccg\const.py modified; restarting server
error closing fd 224
Traceback (most recent call last):
  File "C:\Python27\lib\site-packages\tornado-3.1.1-py2.7.egg\tornado\ioloop.py", line 519, in close
    os.close(fd)
OSError: [Errno 9] Bad file descriptor
error closing fd 156
Traceback (most recent call last):
  File "C:\Python27\lib\site-packages\tornado-3.1.1-py2.7.egg\tornado\ioloop.py", line 519, in close
    os.close(fd)
OSError: [Errno 9] Bad file descriptor
F:\ccg\const.py modified; restarting server
error closing fd 224
Traceback (most recent call last):
  File "C:\Python27\lib\site-packages\tornado-3.1.1-py2.7.egg\tornado\ioloop.py", line 519, in close
    os.close(fd)
OSError: [Errno 9] Bad file descriptor
error closing fd 156
Traceback (most recent call last):
  File "C:\Python27\lib\site-packages\tornado-3.1.1-py2.7.egg\tornado\ioloop.py", line 519, in close
    os.close(fd)
OSError: [Errno 9] Bad file descriptor
F:\ccg\const.py modified; restarting server
error closing fd 224
Traceback (most recent call last):
  File "C:\Python27\lib\site-packages\tornado-3.1.1-py2.7.egg\tornado\ioloop.py", line 519, in close
    os.close(fd)
OSError: [Errno 9] Bad file descriptor
error closing fd 156
Traceback (most recent call last):
  File "C:\Python27\lib\site-packages\tornado-3.1.1-py2.7.egg\tornado\ioloop.py", line 519, in close
    os.close(fd)
OSError: [Errno 9] Bad file descriptor
F:\ccg\const.py modified; restarting server
error closing fd 224
Traceback (most recent call last):
  File "C:\Python27\lib\site-packages\tornado-3.1.1-py2.7.egg\tornado\ioloop.py", line 519, in close
    os.close(fd)
OSError: [Errno 9] Bad file descriptor
error closing fd 156
Traceback (most recent call last):
  File "C:\Python27\lib\site-packages\tornado-3.1.1-py2.7.egg\tornado\ioloop.py", line 519, in close
    os.close(fd)
OSError: [Errno 9] Bad file descriptor
F:\ccg\const.py modified; restarting server
error closing fd 224
Traceback (most recent call last):
  File "C:\Python27\lib\site-packages\tornado-3.1.1-py2.7.egg\tornado\ioloop.py", line 519, in close
    os.close(fd)
OSError: [Errno 9] Bad file descriptor
error closing fd 156
Traceback (most recent call last):
  File "C:\Python27\lib\site-packages\tornado-3.1.1-py2.7.egg\tornado\ioloop.py", line 519, in close
    os.close(fd)
OSError: [Errno 9] Bad file descriptor
F:\ccg\const.py modified; restarting server
error closing fd 224
Traceback (most recent call last):
  File "C:\Python27\lib\site-packages\tornado-3.1.1-py2.7.egg\tornado\ioloop.py", line 519, in close
    os.close(fd)
OSError: [Errno 9] Bad file descriptor
error closing fd 156
Traceback (most recent call last):
  File "C:\Python27\lib\site-packages\tornado-3.1.1-py2.7.egg\tornado\ioloop.py", line 519, in close
    os.close(fd)
OSError: [Errno 9] Bad file descriptor
F:\ccg\const.py modified; restarting server
error closing fd 224
Traceback (most recent call last):
  File "C:\Python27\lib\site-packages\tornado-3.1.1-py2.7.egg\tornado\ioloop.py", line 519, in close
    os.close(fd)
OSError: [Errno 9] Bad file descriptor
error closing fd 156
Traceback (most recent call last):
  File "C:\Python27\lib\site-packages\tornado-3.1.1-py2.7.egg\tornado\ioloop.py", line 519, in close
    os.close(fd)
OSError: [Errno 9] Bad file descriptor
./model\SkillModel.py modified; restarting server
error closing fd 224
Traceback (most recent call last):
  File "C:\Python27\lib\site-packages\tornado-3.1.1-py2.7.egg\tornado\ioloop.py", line 519, in close
    os.close(fd)
OSError: [Errno 9] Bad file descriptor
error closing fd 156
Traceback (most recent call last):
  File "C:\Python27\lib\site-packages\tornado-3.1.1-py2.7.egg\tornado\ioloop.py", line 519, in close
    os.close(fd)
OSError: [Errno 9] Bad file descriptor
./model\SkillModel.py modified; restarting server
error closing fd 224
Traceback (most recent call last):
  File "C:\Python27\lib\site-packages\tornado-3.1.1-py2.7.egg\tornado\ioloop.py", line 519, in close
    os.close(fd)
OSError: [Errno 9] Bad file descriptor
error closing fd 156
Traceback (most recent call last):
  File "C:\Python27\lib\site-packages\tornado-3.1.1-py2.7.egg\tornado\ioloop.py", line 519, in close
    os.close(fd)
OSError: [Errno 9] Bad file descriptor
./model\SkillModel.py modified; restarting server
error closing fd 224
Traceback (most recent call last):
  File "C:\Python27\lib\site-packages\tornado-3.1.1-py2.7.egg\tornado\ioloop.py", line 519, in close
    os.close(fd)
OSError: [Errno 9] Bad file descriptor
error closing fd 156
Traceback (most recent call last):
  File "C:\Python27\lib\site-packages\tornado-3.1.1-py2.7.egg\tornado\ioloop.py", line 519, in close
    os.close(fd)
OSError: [Errno 9] Bad file descriptor
./model\SkillModel.py modified; restarting server
error closing fd 224
Traceback (most recent call last):
  File "C:\Python27\lib\site-packages\tornado-3.1.1-py2.7.egg\tornado\ioloop.py", line 519, in close
    os.close(fd)
OSError: [Errno 9] Bad file descriptor
error closing fd 156
Traceback (most recent call last):
  File "C:\Python27\lib\site-packages\tornado-3.1.1-py2.7.egg\tornado\ioloop.py", line 519, in close
    os.close(fd)
OSError: [Errno 9] Bad file descriptor
./model\SkillModel.py modified; restarting server
error closing fd 224
Traceback (most recent call last):
  File "C:\Python27\lib\site-packages\tornado-3.1.1-py2.7.egg\tornado\ioloop.py", line 519, in close
    os.close(fd)
OSError: [Errno 9] Bad file descriptor
error closing fd 156
Traceback (most recent call last):
  File "C:\Python27\lib\site-packages\tornado-3.1.1-py2.7.egg\tornado\ioloop.py", line 519, in close
    os.close(fd)
OSError: [Errno 9] Bad file descriptor
./model\SkillModel.py modified; restarting server
error closing fd 224
Traceback (most recent call last):
  File "C:\Python27\lib\site-packages\tornado-3.1.1-py2.7.egg\tornado\ioloop.py", line 519, in close
    os.close(fd)
OSError: [Errno 9] Bad file descriptor
error closing fd 156
Traceback (most recent call last):
  File "C:\Python27\lib\site-packages\tornado-3.1.1-py2.7.egg\tornado\ioloop.py", line 519, in close
    os.close(fd)
OSError: [Errno 9] Bad file descriptor
./model\SkillModel.py modified; restarting server
error closing fd 224
Traceback (most recent call last):
  File "C:\Python27\lib\site-packages\tornado-3.1.1-py2.7.egg\tornado\ioloop.py", line 519, in close
    os.close(fd)
OSError: [Errno 9] Bad file descriptor
error closing fd 156
Traceback (most recent call last):
  File "C:\Python27\lib\site-packages\tornado-3.1.1-py2.7.egg\tornado\ioloop.py", line 519, in close
    os.close(fd)
OSError: [Errno 9] Bad file descriptor
./model\SkillModel.py modified; restarting server
error closing fd 224
Traceback (most recent call last):
  File "C:\Python27\lib\site-packages\tornado-3.1.1-py2.7.egg\tornado\ioloop.py", line 519, in close
    os.close(fd)
OSError: [Errno 9] Bad file descriptor
error closing fd 156
Traceback (most recent call last):
  File "C:\Python27\lib\site-packages\tornado-3.1.1-py2.7.egg\tornado\ioloop.py", line 519, in close
    os.close(fd)
OSError: [Errno 9] Bad file descriptor
./model\SkillModel.py modified; restarting server
error closing fd 224
Traceback (most recent call last):
  File "C:\Python27\lib\site-packages\tornado-3.1.1-py2.7.egg\tornado\ioloop.py", line 519, in close
    os.close(fd)
OSError: [Errno 9] Bad file descriptor
error closing fd 156
Traceback (most recent call last):
  File "C:\Python27\lib\site-packages\tornado-3.1.1-py2.7.egg\tornado\ioloop.py", line 519, in close
    os.close(fd)
OSError: [Errno 9] Bad file descriptor
./model\SkillModel.py modified; restarting server
error closing fd 224
Traceback (most recent call last):
  File "C:\Python27\lib\site-packages\tornado-3.1.1-py2.7.egg\tornado\ioloop.py", line 519, in close
    os.close(fd)
OSError: [Errno 9] Bad file descriptor
error closing fd 156
Traceback (most recent call last):
  File "C:\Python27\lib\site-packages\tornado-3.1.1-py2.7.egg\tornado\ioloop.py", line 519, in close
    os.close(fd)
OSError: [Errno 9] Bad file descriptor
Uncaught exception, closing connection.
Traceback (most recent call last):
  File "C:\Python27\lib\site-packages\tornado-3.1.1-py2.7.egg\tornado\iostream.py", line 341, in wrapper
    callback(*args)
  File "C:\Python27\lib\site-packages\tornado-3.1.1-py2.7.egg\tornado\stack_context.py", line 331, in wrapped
    raise_exc_info(exc)
  File "C:\Python27\lib\site-packages\tornado-3.1.1-py2.7.egg\tornado\stack_context.py", line 302, in wrapped
    ret = fn(*args, **kwargs)
  File "server.py", line 179, in send_message
    res= self.parse_message(data)
  File "server.py", line 149, in parse_message
    data, push_data= func(params)
  File "F:\ccg\service\FightService.py", line 37, in searchRoom
    return self.createRoom(params)
  File "F:\ccg\service\FightService.py", line 94, in createRoom
    hero1= HeroModel.getSystemOrUserHerosById(uuid, heroId1)
  File "./model\HeroModel.py", line 166, in getSystemOrUserHerosById
    data= self.getUserHerosById(userId, id)
  File "./model\HeroModel.py", line 144, in getUserHerosById
    heroInfo = self.getHerosByJob(data['job'])
TypeError: 'NoneType' object has no attribute '__getitem__'
Exception in callback <functools.partial object at 0x02ADB810>
Traceback (most recent call last):
  File "C:\Python27\lib\site-packages\tornado-3.1.1-py2.7.egg\tornado\ioloop.py", line 458, in _run_callback
    callback()
  File "C:\Python27\lib\site-packages\tornado-3.1.1-py2.7.egg\tornado\stack_context.py", line 331, in wrapped
    raise_exc_info(exc)
  File "C:\Python27\lib\site-packages\tornado-3.1.1-py2.7.egg\tornado\stack_context.py", line 302, in wrapped
    ret = fn(*args, **kwargs)
  File "C:\Python27\lib\site-packages\tornado-3.1.1-py2.7.egg\tornado\iostream.py", line 341, in wrapper
    callback(*args)
  File "C:\Python27\lib\site-packages\tornado-3.1.1-py2.7.egg\tornado\stack_context.py", line 331, in wrapped
    raise_exc_info(exc)
  File "C:\Python27\lib\site-packages\tornado-3.1.1-py2.7.egg\tornado\stack_context.py", line 302, in wrapped
    ret = fn(*args, **kwargs)
  File "server.py", line 179, in send_message
    res= self.parse_message(data)
  File "server.py", line 149, in parse_message
    data, push_data= func(params)
  File "F:\ccg\service\FightService.py", line 37, in searchRoom
    return self.createRoom(params)
  File "F:\ccg\service\FightService.py", line 94, in createRoom
    hero1= HeroModel.getSystemOrUserHerosById(uuid, heroId1)
  File "./model\HeroModel.py", line 166, in getSystemOrUserHerosById
    data= self.getUserHerosById(userId, id)
  File "./model\HeroModel.py", line 144, in getUserHerosById
    heroInfo = self.getHerosByJob(data['job'])
TypeError: 'NoneType' object has no attribute '__getitem__'
Uncaught exception, closing connection.
Traceback (most recent call last):
  File "C:\Python27\lib\site-packages\tornado-3.1.1-py2.7.egg\tornado\iostream.py", line 341, in wrapper
    callback(*args)
  File "C:\Python27\lib\site-packages\tornado-3.1.1-py2.7.egg\tornado\stack_context.py", line 331, in wrapped
    raise_exc_info(exc)
  File "C:\Python27\lib\site-packages\tornado-3.1.1-py2.7.egg\tornado\stack_context.py", line 302, in wrapped
    ret = fn(*args, **kwargs)
  File "server.py", line 179, in send_message
    res= self.parse_message(data)
  File "server.py", line 149, in parse_message
    data, push_data= func(params)
  File "F:\ccg\service\FightService.py", line 1222, in UseSkillCard
    SkillModel.triggerEffects(room, effects, 2, target)
  File "./model\SkillModel.py", line 120, in triggerEffects
    self.doEffect(room, pos, effect, uniqids)
  File "./model\SkillModel.py", line 135, in doEffect
    if effect['type']== EFFECT_TYPE_CHARGE:
NameError: global name 'EFFECT_TYPE_CHARGE' is not defined
Exception in callback <functools.partial object at 0x02B49E70>
Traceback (most recent call last):
  File "C:\Python27\lib\site-packages\tornado-3.1.1-py2.7.egg\tornado\ioloop.py", line 458, in _run_callback
    callback()
  File "C:\Python27\lib\site-packages\tornado-3.1.1-py2.7.egg\tornado\stack_context.py", line 331, in wrapped
    raise_exc_info(exc)
  File "C:\Python27\lib\site-packages\tornado-3.1.1-py2.7.egg\tornado\stack_context.py", line 302, in wrapped
    ret = fn(*args, **kwargs)
  File "C:\Python27\lib\site-packages\tornado-3.1.1-py2.7.egg\tornado\iostream.py", line 341, in wrapper
    callback(*args)
  File "C:\Python27\lib\site-packages\tornado-3.1.1-py2.7.egg\tornado\stack_context.py", line 331, in wrapped
    raise_exc_info(exc)
  File "C:\Python27\lib\site-packages\tornado-3.1.1-py2.7.egg\tornado\stack_context.py", line 302, in wrapped
    ret = fn(*args, **kwargs)
  File "server.py", line 179, in send_message
    res= self.parse_message(data)
  File "server.py", line 149, in parse_message
    data, push_data= func(params)
  File "F:\ccg\service\FightService.py", line 1222, in UseSkillCard
    SkillModel.triggerEffects(room, effects, 2, target)
  File "./model\SkillModel.py", line 120, in triggerEffects
    self.doEffect(room, pos, effect, uniqids)
  File "./model\SkillModel.py", line 135, in doEffect
    if effect['type']== EFFECT_TYPE_CHARGE:
NameError: global name 'EFFECT_TYPE_CHARGE' is not defined
Uncaught exception, closing connection.
Traceback (most recent call last):
  File "C:\Python27\lib\site-packages\tornado-3.1.1-py2.7.egg\tornado\iostream.py", line 341, in wrapper
    callback(*args)
  File "C:\Python27\lib\site-packages\tornado-3.1.1-py2.7.egg\tornado\stack_context.py", line 331, in wrapped
    raise_exc_info(exc)
  File "C:\Python27\lib\site-packages\tornado-3.1.1-py2.7.egg\tornado\stack_context.py", line 302, in wrapped
    ret = fn(*args, **kwargs)
  File "server.py", line 179, in send_message
    res= self.parse_message(data)
  File "server.py", line 149, in parse_message
    data, push_data= func(params)
  File "F:\ccg\service\FightService.py", line 1152, in UseSkillCard
    SkillModel.triggerEffects(room, effects, 1, target)
  File "./model\SkillModel.py", line 120, in triggerEffects
    self.doEffect(room, pos, effect, uniqids)
  File "./model\SkillModel.py", line 135, in doEffect
    if effect['type']== EFFECT_TYPE_CHARGE:
NameError: global name 'EFFECT_TYPE_CHARGE' is not defined
Exception in callback <functools.partial object at 0x02B49EA0>
Traceback (most recent call last):
  File "C:\Python27\lib\site-packages\tornado-3.1.1-py2.7.egg\tornado\ioloop.py", line 458, in _run_callback
    callback()
  File "C:\Python27\lib\site-packages\tornado-3.1.1-py2.7.egg\tornado\stack_context.py", line 331, in wrapped
    raise_exc_info(exc)
  File "C:\Python27\lib\site-packages\tornado-3.1.1-py2.7.egg\tornado\stack_context.py", line 302, in wrapped
    ret = fn(*args, **kwargs)
  File "C:\Python27\lib\site-packages\tornado-3.1.1-py2.7.egg\tornado\iostream.py", line 341, in wrapper
    callback(*args)
  File "C:\Python27\lib\site-packages\tornado-3.1.1-py2.7.egg\tornado\stack_context.py", line 331, in wrapped
    raise_exc_info(exc)
  File "C:\Python27\lib\site-packages\tornado-3.1.1-py2.7.egg\tornado\stack_context.py", line 302, in wrapped
    ret = fn(*args, **kwargs)
  File "server.py", line 179, in send_message
    res= self.parse_message(data)
  File "server.py", line 149, in parse_message
    data, push_data= func(params)
  File "F:\ccg\service\FightService.py", line 1152, in UseSkillCard
    SkillModel.triggerEffects(room, effects, 1, target)
  File "./model\SkillModel.py", line 120, in triggerEffects
    self.doEffect(room, pos, effect, uniqids)
  File "./model\SkillModel.py", line 135, in doEffect
    if effect['type']== EFFECT_TYPE_CHARGE:
NameError: global name 'EFFECT_TYPE_CHARGE' is not defined
./model\SkillModel.py modified; restarting server
error closing fd 224
Traceback (most recent call last):
  File "C:\Python27\lib\site-packages\tornado-3.1.1-py2.7.egg\tornado\ioloop.py", line 519, in close
    os.close(fd)
OSError: [Errno 9] Bad file descriptor
error closing fd 156
Traceback (most recent call last):
  File "C:\Python27\lib\site-packages\tornado-3.1.1-py2.7.egg\tornado\ioloop.py", line 519, in close
    os.close(fd)
OSError: [Errno 9] Bad file descriptor
F:\ccg\model\EffectHelperModel.py modified; restarting server
error closing fd 224
Traceback (most recent call last):
  File "C:\Python27\lib\site-packages\tornado-3.1.1-py2.7.egg\tornado\ioloop.py", line 519, in close
    os.close(fd)
OSError: [Errno 9] Bad file descriptor
error closing fd 156
Traceback (most recent call last):
  File "C:\Python27\lib\site-packages\tornado-3.1.1-py2.7.egg\tornado\ioloop.py", line 519, in close
    os.close(fd)
OSError: [Errno 9] Bad file descriptor
error closing fd 672
Traceback (most recent call last):
  File "C:\Python27\lib\site-packages\tornado-3.1.1-py2.7.egg\tornado\ioloop.py", line 519, in close
    os.close(fd)
OSError: [Errno 9] Bad file descriptor
error closing fd 676
Traceback (most recent call last):
  File "C:\Python27\lib\site-packages\tornado-3.1.1-py2.7.egg\tornado\ioloop.py", line 519, in close
    os.close(fd)
OSError: [Errno 9] Bad file descriptor
F:\ccg\model\EffectHelperModel.py modified; restarting server
error closing fd 224
Traceback (most recent call last):
  File "C:\Python27\lib\site-packages\tornado-3.1.1-py2.7.egg\tornado\ioloop.py", line 519, in close
    os.close(fd)
OSError: [Errno 9] Bad file descriptor
error closing fd 156
Traceback (most recent call last):
  File "C:\Python27\lib\site-packages\tornado-3.1.1-py2.7.egg\tornado\ioloop.py", line 519, in close
    os.close(fd)
OSError: [Errno 9] Bad file descriptor
F:\ccg\model\EffectHelperModel.py modified; restarting server
error closing fd 224
Traceback (most recent call last):
  File "C:\Python27\lib\site-packages\tornado-3.1.1-py2.7.egg\tornado\ioloop.py", line 519, in close
    os.close(fd)
OSError: [Errno 9] Bad file descriptor
error closing fd 156
Traceback (most recent call last):
  File "C:\Python27\lib\site-packages\tornado-3.1.1-py2.7.egg\tornado\ioloop.py", line 519, in close
    os.close(fd)
OSError: [Errno 9] Bad file descriptor
F:\ccg\model\EffectHelperModel.py modified; restarting server
error closing fd 224
Traceback (most recent call last):
  File "C:\Python27\lib\site-packages\tornado-3.1.1-py2.7.egg\tornado\ioloop.py", line 519, in close
    os.close(fd)
OSError: [Errno 9] Bad file descriptor
error closing fd 156
Traceback (most recent call last):
  File "C:\Python27\lib\site-packages\tornado-3.1.1-py2.7.egg\tornado\ioloop.py", line 519, in close
    os.close(fd)
OSError: [Errno 9] Bad file descriptor
F:\ccg\model\EffectHelperModel.py modified; restarting server
error closing fd 224
Traceback (most recent call last):
  File "C:\Python27\lib\site-packages\tornado-3.1.1-py2.7.egg\tornado\ioloop.py", line 519, in close
    os.close(fd)
OSError: [Errno 9] Bad file descriptor
error closing fd 156
Traceback (most recent call last):
  File "C:\Python27\lib\site-packages\tornado-3.1.1-py2.7.egg\tornado\ioloop.py", line 519, in close
    os.close(fd)
OSError: [Errno 9] Bad file descriptor
Uncaught exception, closing connection.
Traceback (most recent call last):
  File "C:\Python27\lib\site-packages\tornado-3.1.1-py2.7.egg\tornado\iostream.py", line 341, in wrapper
    callback(*args)
  File "C:\Python27\lib\site-packages\tornado-3.1.1-py2.7.egg\tornado\stack_context.py", line 331, in wrapped
    raise_exc_info(exc)
  File "C:\Python27\lib\site-packages\tornado-3.1.1-py2.7.egg\tornado\stack_context.py", line 302, in wrapped
    ret = fn(*args, **kwargs)
  File "server.py", line 179, in send_message
    res= self.parse_message(data)
  File "server.py", line 149, in parse_message
    data, push_data= func(params)
  File "F:\ccg\service\FightService.py", line 608, in turnEnd
    EffectHelperModel.turnEndEffectCallBack(room, 1)
  File "./model\EffectHelperModel.py", line 328, in turnEndEffectCallBack
    if isinstance(room, dict)== False or isinstance(uniqid, int)== False or type== '' or (pos!=1 and pos!= 2):
NameError: global name 'uniqid' is not defined
Exception in callback <functools.partial object at 0x02A03D20>
Traceback (most recent call last):
  File "C:\Python27\lib\site-packages\tornado-3.1.1-py2.7.egg\tornado\ioloop.py", line 458, in _run_callback
    callback()
  File "C:\Python27\lib\site-packages\tornado-3.1.1-py2.7.egg\tornado\stack_context.py", line 331, in wrapped
    raise_exc_info(exc)
  File "C:\Python27\lib\site-packages\tornado-3.1.1-py2.7.egg\tornado\stack_context.py", line 302, in wrapped
    ret = fn(*args, **kwargs)
  File "C:\Python27\lib\site-packages\tornado-3.1.1-py2.7.egg\tornado\iostream.py", line 341, in wrapper
    callback(*args)
  File "C:\Python27\lib\site-packages\tornado-3.1.1-py2.7.egg\tornado\stack_context.py", line 331, in wrapped
    raise_exc_info(exc)
  File "C:\Python27\lib\site-packages\tornado-3.1.1-py2.7.egg\tornado\stack_context.py", line 302, in wrapped
    ret = fn(*args, **kwargs)
  File "server.py", line 179, in send_message
    res= self.parse_message(data)
  File "server.py", line 149, in parse_message
    data, push_data= func(params)
  File "F:\ccg\service\FightService.py", line 608, in turnEnd
    EffectHelperModel.turnEndEffectCallBack(room, 1)
  File "./model\EffectHelperModel.py", line 328, in turnEndEffectCallBack
    if isinstance(room, dict)== False or isinstance(uniqid, int)== False or type== '' or (pos!=1 and pos!= 2):
NameError: global name 'uniqid' is not defined
F:\ccg\model\EffectHelperModel.py modified; restarting server
error closing fd 224
Traceback (most recent call last):
  File "C:\Python27\lib\site-packages\tornado-3.1.1-py2.7.egg\tornado\ioloop.py", line 519, in close
    os.close(fd)
OSError: [Errno 9] Bad file descriptor
error closing fd 664
Traceback (most recent call last):
  File "C:\Python27\lib\site-packages\tornado-3.1.1-py2.7.egg\tornado\ioloop.py", line 519, in close
    os.close(fd)
OSError: [Errno 9] Bad file descriptor
error closing fd 156
Traceback (most recent call last):
  File "C:\Python27\lib\site-packages\tornado-3.1.1-py2.7.egg\tornado\ioloop.py", line 519, in close
    os.close(fd)
OSError: [Errno 9] Bad file descriptor
Uncaught exception, closing connection.
Traceback (most recent call last):
  File "C:\Python27\lib\site-packages\tornado-3.1.1-py2.7.egg\tornado\iostream.py", line 341, in wrapper
    callback(*args)
  File "C:\Python27\lib\site-packages\tornado-3.1.1-py2.7.egg\tornado\stack_context.py", line 331, in wrapped
    raise_exc_info(exc)
  File "C:\Python27\lib\site-packages\tornado-3.1.1-py2.7.egg\tornado\stack_context.py", line 302, in wrapped
    ret = fn(*args, **kwargs)
  File "server.py", line 179, in send_message
    res= self.parse_message(data)
  File "server.py", line 149, in parse_message
    data, push_data= func(params)
  File "F:\ccg\service\FightService.py", line 621, in turnEnd
    EffectHelperModel.turnEndEffectCallBack(room, 2)
  File "./model\EffectHelperModel.py", line 340, in turnEndEffectCallBack
    map(doEffectCallBack, keys, types)
  File "./model\EffectHelperModel.py", line 335, in doEffectCallBack
    list= zrange(key, 0, -1, withscores=False, score_cast_func=int)
NameError: global name 'zrange' is not defined
Exception in callback <functools.partial object at 0x02B27D80>
Traceback (most recent call last):
  File "C:\Python27\lib\site-packages\tornado-3.1.1-py2.7.egg\tornado\ioloop.py", line 458, in _run_callback
    callback()
  File "C:\Python27\lib\site-packages\tornado-3.1.1-py2.7.egg\tornado\stack_context.py", line 331, in wrapped
    raise_exc_info(exc)
  File "C:\Python27\lib\site-packages\tornado-3.1.1-py2.7.egg\tornado\stack_context.py", line 302, in wrapped
    ret = fn(*args, **kwargs)
  File "C:\Python27\lib\site-packages\tornado-3.1.1-py2.7.egg\tornado\iostream.py", line 341, in wrapper
    callback(*args)
  File "C:\Python27\lib\site-packages\tornado-3.1.1-py2.7.egg\tornado\stack_context.py", line 331, in wrapped
    raise_exc_info(exc)
  File "C:\Python27\lib\site-packages\tornado-3.1.1-py2.7.egg\tornado\stack_context.py", line 302, in wrapped
    ret = fn(*args, **kwargs)
  File "server.py", line 179, in send_message
    res= self.parse_message(data)
  File "server.py", line 149, in parse_message
    data, push_data= func(params)
  File "F:\ccg\service\FightService.py", line 621, in turnEnd
    EffectHelperModel.turnEndEffectCallBack(room, 2)
  File "./model\EffectHelperModel.py", line 340, in turnEndEffectCallBack
    map(doEffectCallBack, keys, types)
  File "./model\EffectHelperModel.py", line 335, in doEffectCallBack
    list= zrange(key, 0, -1, withscores=False, score_cast_func=int)
NameError: global name 'zrange' is not defined
F:\ccg\model\EffectHelperModel.py modified; restarting server
error closing fd 224
Traceback (most recent call last):
  File "C:\Python27\lib\site-packages\tornado-3.1.1-py2.7.egg\tornado\ioloop.py", line 519, in close
    os.close(fd)
OSError: [Errno 9] Bad file descriptor
error closing fd 156
Traceback (most recent call last):
  File "C:\Python27\lib\site-packages\tornado-3.1.1-py2.7.egg\tornado\ioloop.py", line 519, in close
    os.close(fd)
OSError: [Errno 9] Bad file descriptor
error closing fd 676
Traceback (most recent call last):
  File "C:\Python27\lib\site-packages\tornado-3.1.1-py2.7.egg\tornado\ioloop.py", line 519, in close
    os.close(fd)
OSError: [Errno 9] Bad file descriptor
F:\ccg\model\EffectHelperModel.py modified; restarting server
error closing fd 224
Traceback (most recent call last):
  File "C:\Python27\lib\site-packages\tornado-3.1.1-py2.7.egg\tornado\ioloop.py", line 519, in close
    os.close(fd)
OSError: [Errno 9] Bad file descriptor
error closing fd 156
Traceback (most recent call last):
  File "C:\Python27\lib\site-packages\tornado-3.1.1-py2.7.egg\tornado\ioloop.py", line 519, in close
    os.close(fd)
OSError: [Errno 9] Bad file descriptor
error closing fd 692
Traceback (most recent call last):
  File "C:\Python27\lib\site-packages\tornado-3.1.1-py2.7.egg\tornado\ioloop.py", line 519, in close
    os.close(fd)
OSError: [Errno 9] Bad file descriptor
error closing fd 696
Traceback (most recent call last):
  File "C:\Python27\lib\site-packages\tornado-3.1.1-py2.7.egg\tornado\ioloop.py", line 519, in close
    os.close(fd)
OSError: [Errno 9] Bad file descriptor
F:\ccg\model\EffectHelperModel.py modified; restarting server
error closing fd 224
Traceback (most recent call last):
  File "C:\Python27\lib\site-packages\tornado-3.1.1-py2.7.egg\tornado\ioloop.py", line 519, in close
    os.close(fd)
OSError: [Errno 9] Bad file descriptor
error closing fd 156
Traceback (most recent call last):
  File "C:\Python27\lib\site-packages\tornado-3.1.1-py2.7.egg\tornado\ioloop.py", line 519, in close
    os.close(fd)
OSError: [Errno 9] Bad file descriptor
F:\ccg\const.py modified; restarting server
error closing fd 224
Traceback (most recent call last):
  File "C:\Python27\lib\site-packages\tornado-3.1.1-py2.7.egg\tornado\ioloop.py", line 519, in close
    os.close(fd)
OSError: [Errno 9] Bad file descriptor
error closing fd 156
Traceback (most recent call last):
  File "C:\Python27\lib\site-packages\tornado-3.1.1-py2.7.egg\tornado\ioloop.py", line 519, in close
    os.close(fd)
OSError: [Errno 9] Bad file descriptor
F:\ccg\model\RoomModel.py modified; restarting server
error closing fd 224
Traceback (most recent call last):
  File "C:\Python27\lib\site-packages\tornado-3.1.1-py2.7.egg\tornado\ioloop.py", line 519, in close
    os.close(fd)
OSError: [Errno 9] Bad file descriptor
error closing fd 660
Traceback (most recent call last):
  File "C:\Python27\lib\site-packages\tornado-3.1.1-py2.7.egg\tornado\ioloop.py", line 519, in close
    os.close(fd)
OSError: [Errno 9] Bad file descriptor
error closing fd 664
Traceback (most recent call last):
  File "C:\Python27\lib\site-packages\tornado-3.1.1-py2.7.egg\tornado\ioloop.py", line 519, in close
    os.close(fd)
OSError: [Errno 9] Bad file descriptor
error closing fd 156
Traceback (most recent call last):
  File "C:\Python27\lib\site-packages\tornado-3.1.1-py2.7.egg\tornado\ioloop.py", line 519, in close
    os.close(fd)
OSError: [Errno 9] Bad file descriptor
