Uncaught exception, closing connection.
Traceback (most recent call last):
  File "C:\Python27\lib\site-packages\tornado-3.1.1-py2.7.egg\tornado\iostream.py", line 341, in wrapper
    callback(*args)
  File "C:\Python27\lib\site-packages\tornado-3.1.1-py2.7.egg\tornado\stack_context.py", line 331, in wrapped
    raise_exc_info(exc)
  File "C:\Python27\lib\site-packages\tornado-3.1.1-py2.7.egg\tornado\stack_context.py", line 302, in wrapped
    ret = fn(*args, **kwargs)
  File "server.py", line 175, in send_message
    res= self.parse_message(data)
  File "server.py", line 145, in parse_message
    data, push_data= func(params)
  File "F:\ccg\service\FightService.py", line 37, in searchRoom
    return self.createRoom(params)
  File "F:\ccg\service\FightService.py", line 94, in createRoom
    hero1= HeroModel.getSystemOrUserHerosById(uuid, heroId1)
  File "./model\HeroModel.py", line 166, in getSystemOrUserHerosById
    data= self.getUserHerosById(userId, id)
  File "./model\HeroModel.py", line 144, in getUserHerosById
    heroInfo = self.getHerosByJob(data['job'])
TypeError: 'NoneType' object has no attribute '__getitem__'
Exception in callback <functools.partial object at 0x02A7DAE0>
Traceback (most recent call last):
  File "C:\Python27\lib\site-packages\tornado-3.1.1-py2.7.egg\tornado\ioloop.py", line 458, in _run_callback
    callback()
  File "C:\Python27\lib\site-packages\tornado-3.1.1-py2.7.egg\tornado\stack_context.py", line 331, in wrapped
    raise_exc_info(exc)
  File "C:\Python27\lib\site-packages\tornado-3.1.1-py2.7.egg\tornado\stack_context.py", line 302, in wrapped
    ret = fn(*args, **kwargs)
  File "C:\Python27\lib\site-packages\tornado-3.1.1-py2.7.egg\tornado\iostream.py", line 341, in wrapper
    callback(*args)
  File "C:\Python27\lib\site-packages\tornado-3.1.1-py2.7.egg\tornado\stack_context.py", line 331, in wrapped
    raise_exc_info(exc)
  File "C:\Python27\lib\site-packages\tornado-3.1.1-py2.7.egg\tornado\stack_context.py", line 302, in wrapped
    ret = fn(*args, **kwargs)
  File "server.py", line 175, in send_message
    res= self.parse_message(data)
  File "server.py", line 145, in parse_message
    data, push_data= func(params)
  File "F:\ccg\service\FightService.py", line 37, in searchRoom
    return self.createRoom(params)
  File "F:\ccg\service\FightService.py", line 94, in createRoom
    hero1= HeroModel.getSystemOrUserHerosById(uuid, heroId1)
  File "./model\HeroModel.py", line 166, in getSystemOrUserHerosById
    data= self.getUserHerosById(userId, id)
  File "./model\HeroModel.py", line 144, in getUserHerosById
    heroInfo = self.getHerosByJob(data['job'])
TypeError: 'NoneType' object has no attribute '__getitem__'
Uncaught exception, closing connection.
Traceback (most recent call last):
  File "C:\Python27\lib\site-packages\tornado-3.1.1-py2.7.egg\tornado\iostream.py", line 341, in wrapper
    callback(*args)
  File "C:\Python27\lib\site-packages\tornado-3.1.1-py2.7.egg\tornado\stack_context.py", line 331, in wrapped
    raise_exc_info(exc)
  File "C:\Python27\lib\site-packages\tornado-3.1.1-py2.7.egg\tornado\stack_context.py", line 302, in wrapped
    ret = fn(*args, **kwargs)
  File "server.py", line 175, in send_message
    res= self.parse_message(data)
  File "server.py", line 145, in parse_message
    data, push_data= func(params)
  File "F:\ccg\service\FightService.py", line 37, in searchRoom
    return self.createRoom(params)
  File "F:\ccg\service\FightService.py", line 94, in createRoom
    hero1= HeroModel.getSystemOrUserHerosById(uuid, heroId1)
  File "./model\HeroModel.py", line 166, in getSystemOrUserHerosById
    data= self.getUserHerosById(userId, id)
  File "./model\HeroModel.py", line 144, in getUserHerosById
    heroInfo = self.getHerosByJob(data['job'])
TypeError: 'NoneType' object has no attribute '__getitem__'
Exception in callback <functools.partial object at 0x02AB8EA0>
Traceback (most recent call last):
  File "C:\Python27\lib\site-packages\tornado-3.1.1-py2.7.egg\tornado\ioloop.py", line 458, in _run_callback
    callback()
  File "C:\Python27\lib\site-packages\tornado-3.1.1-py2.7.egg\tornado\stack_context.py", line 331, in wrapped
    raise_exc_info(exc)
  File "C:\Python27\lib\site-packages\tornado-3.1.1-py2.7.egg\tornado\stack_context.py", line 302, in wrapped
    ret = fn(*args, **kwargs)
  File "C:\Python27\lib\site-packages\tornado-3.1.1-py2.7.egg\tornado\iostream.py", line 341, in wrapper
    callback(*args)
  File "C:\Python27\lib\site-packages\tornado-3.1.1-py2.7.egg\tornado\stack_context.py", line 331, in wrapped
    raise_exc_info(exc)
  File "C:\Python27\lib\site-packages\tornado-3.1.1-py2.7.egg\tornado\stack_context.py", line 302, in wrapped
    ret = fn(*args, **kwargs)
  File "server.py", line 175, in send_message
    res= self.parse_message(data)
  File "server.py", line 145, in parse_message
    data, push_data= func(params)
  File "F:\ccg\service\FightService.py", line 37, in searchRoom
    return self.createRoom(params)
  File "F:\ccg\service\FightService.py", line 94, in createRoom
    hero1= HeroModel.getSystemOrUserHerosById(uuid, heroId1)
  File "./model\HeroModel.py", line 166, in getSystemOrUserHerosById
    data= self.getUserHerosById(userId, id)
  File "./model\HeroModel.py", line 144, in getUserHerosById
    heroInfo = self.getHerosByJob(data['job'])
TypeError: 'NoneType' object has no attribute '__getitem__'
F:\ccg\service\FightService.py modified; restarting server
error closing fd 224
Traceback (most recent call last):
  File "C:\Python27\lib\site-packages\tornado-3.1.1-py2.7.egg\tornado\ioloop.py", line 519, in close
    os.close(fd)
OSError: [Errno 9] Bad file descriptor
error closing fd 660
Traceback (most recent call last):
  File "C:\Python27\lib\site-packages\tornado-3.1.1-py2.7.egg\tornado\ioloop.py", line 519, in close
    os.close(fd)
OSError: [Errno 9] Bad file descriptor
error closing fd 664
Traceback (most recent call last):
  File "C:\Python27\lib\site-packages\tornado-3.1.1-py2.7.egg\tornado\ioloop.py", line 519, in close
    os.close(fd)
OSError: [Errno 9] Bad file descriptor
error closing fd 156
Traceback (most recent call last):
  File "C:\Python27\lib\site-packages\tornado-3.1.1-py2.7.egg\tornado\ioloop.py", line 519, in close
    os.close(fd)
OSError: [Errno 9] Bad file descriptor
F:\ccg\service\FightService.py modified; restarting server
error closing fd 224
Traceback (most recent call last):
  File "C:\Python27\lib\site-packages\tornado-3.1.1-py2.7.egg\tornado\ioloop.py", line 519, in close
    os.close(fd)
OSError: [Errno 9] Bad file descriptor
error closing fd 156
Traceback (most recent call last):
  File "C:\Python27\lib\site-packages\tornado-3.1.1-py2.7.egg\tornado\ioloop.py", line 519, in close
    os.close(fd)
OSError: [Errno 9] Bad file descriptor
F:\ccg\errors.py modified; restarting server
error closing fd 224
Traceback (most recent call last):
  File "C:\Python27\lib\site-packages\tornado-3.1.1-py2.7.egg\tornado\ioloop.py", line 519, in close
    os.close(fd)
OSError: [Errno 9] Bad file descriptor
error closing fd 156
Traceback (most recent call last):
  File "C:\Python27\lib\site-packages\tornado-3.1.1-py2.7.egg\tornado\ioloop.py", line 519, in close
    os.close(fd)
OSError: [Errno 9] Bad file descriptor
F:\ccg\errors.py modified; restarting server
error closing fd 224
Traceback (most recent call last):
  File "C:\Python27\lib\site-packages\tornado-3.1.1-py2.7.egg\tornado\ioloop.py", line 519, in close
    os.close(fd)
OSError: [Errno 9] Bad file descriptor
error closing fd 156
Traceback (most recent call last):
  File "C:\Python27\lib\site-packages\tornado-3.1.1-py2.7.egg\tornado\ioloop.py", line 519, in close
    os.close(fd)
OSError: [Errno 9] Bad file descriptor
F:\ccg\service\FightService.py modified; restarting server
error closing fd 224
Traceback (most recent call last):
  File "C:\Python27\lib\site-packages\tornado-3.1.1-py2.7.egg\tornado\ioloop.py", line 519, in close
    os.close(fd)
OSError: [Errno 9] Bad file descriptor
error closing fd 660
Traceback (most recent call last):
  File "C:\Python27\lib\site-packages\tornado-3.1.1-py2.7.egg\tornado\ioloop.py", line 519, in close
    os.close(fd)
OSError: [Errno 9] Bad file descriptor
error closing fd 664
Traceback (most recent call last):
  File "C:\Python27\lib\site-packages\tornado-3.1.1-py2.7.egg\tornado\ioloop.py", line 519, in close
    os.close(fd)
OSError: [Errno 9] Bad file descriptor
error closing fd 156
Traceback (most recent call last):
  File "C:\Python27\lib\site-packages\tornado-3.1.1-py2.7.egg\tornado\ioloop.py", line 519, in close
    os.close(fd)
OSError: [Errno 9] Bad file descriptor
F:\ccg\service\FightService.py modified; restarting server
error closing fd 224
Traceback (most recent call last):
  File "C:\Python27\lib\site-packages\tornado-3.1.1-py2.7.egg\tornado\ioloop.py", line 519, in close
    os.close(fd)
OSError: [Errno 9] Bad file descriptor
error closing fd 156
Traceback (most recent call last):
  File "C:\Python27\lib\site-packages\tornado-3.1.1-py2.7.egg\tornado\ioloop.py", line 519, in close
    os.close(fd)
OSError: [Errno 9] Bad file descriptor
F:\ccg\service\FightService.py modified; restarting server
error closing fd 224
Traceback (most recent call last):
  File "C:\Python27\lib\site-packages\tornado-3.1.1-py2.7.egg\tornado\ioloop.py", line 519, in close
    os.close(fd)
OSError: [Errno 9] Bad file descriptor
error closing fd 156
Traceback (most recent call last):
  File "C:\Python27\lib\site-packages\tornado-3.1.1-py2.7.egg\tornado\ioloop.py", line 519, in close
    os.close(fd)
OSError: [Errno 9] Bad file descriptor
F:\ccg\service\FightService.py modified; restarting server
error closing fd 224
Traceback (most recent call last):
  File "C:\Python27\lib\site-packages\tornado-3.1.1-py2.7.egg\tornado\ioloop.py", line 519, in close
    os.close(fd)
OSError: [Errno 9] Bad file descriptor
error closing fd 156
Traceback (most recent call last):
  File "C:\Python27\lib\site-packages\tornado-3.1.1-py2.7.egg\tornado\ioloop.py", line 519, in close
    os.close(fd)
OSError: [Errno 9] Bad file descriptor
F:\ccg\service\FightService.py modified; restarting server
error closing fd 224
Traceback (most recent call last):
  File "C:\Python27\lib\site-packages\tornado-3.1.1-py2.7.egg\tornado\ioloop.py", line 519, in close
    os.close(fd)
OSError: [Errno 9] Bad file descriptor
error closing fd 156
Traceback (most recent call last):
  File "C:\Python27\lib\site-packages\tornado-3.1.1-py2.7.egg\tornado\ioloop.py", line 519, in close
    os.close(fd)
OSError: [Errno 9] Bad file descriptor
F:\ccg\service\FightService.py modified; restarting server
error closing fd 224
Traceback (most recent call last):
  File "C:\Python27\lib\site-packages\tornado-3.1.1-py2.7.egg\tornado\ioloop.py", line 519, in close
    os.close(fd)
OSError: [Errno 9] Bad file descriptor
error closing fd 156
Traceback (most recent call last):
  File "C:\Python27\lib\site-packages\tornado-3.1.1-py2.7.egg\tornado\ioloop.py", line 519, in close
    os.close(fd)
OSError: [Errno 9] Bad file descriptor
F:\ccg\service\FightService.py modified; restarting server
error closing fd 224
Traceback (most recent call last):
  File "C:\Python27\lib\site-packages\tornado-3.1.1-py2.7.egg\tornado\ioloop.py", line 519, in close
    os.close(fd)
OSError: [Errno 9] Bad file descriptor
error closing fd 660
Traceback (most recent call last):
  File "C:\Python27\lib\site-packages\tornado-3.1.1-py2.7.egg\tornado\ioloop.py", line 519, in close
    os.close(fd)
OSError: [Errno 9] Bad file descriptor
error closing fd 672
Traceback (most recent call last):
  File "C:\Python27\lib\site-packages\tornado-3.1.1-py2.7.egg\tornado\ioloop.py", line 519, in close
    os.close(fd)
OSError: [Errno 9] Bad file descriptor
error closing fd 156
Traceback (most recent call last):
  File "C:\Python27\lib\site-packages\tornado-3.1.1-py2.7.egg\tornado\ioloop.py", line 519, in close
    os.close(fd)
OSError: [Errno 9] Bad file descriptor
F:\ccg\service\FightService.py modified; restarting server
error closing fd 224
Traceback (most recent call last):
  File "C:\Python27\lib\site-packages\tornado-3.1.1-py2.7.egg\tornado\ioloop.py", line 519, in close
    os.close(fd)
OSError: [Errno 9] Bad file descriptor
error closing fd 156
Traceback (most recent call last):
  File "C:\Python27\lib\site-packages\tornado-3.1.1-py2.7.egg\tornado\ioloop.py", line 519, in close
    os.close(fd)
OSError: [Errno 9] Bad file descriptor
F:\ccg\model\EffectModel.py modified; restarting server
error closing fd 224
Traceback (most recent call last):
  File "C:\Python27\lib\site-packages\tornado-3.1.1-py2.7.egg\tornado\ioloop.py", line 519, in close
    os.close(fd)
OSError: [Errno 9] Bad file descriptor
error closing fd 660
Traceback (most recent call last):
  File "C:\Python27\lib\site-packages\tornado-3.1.1-py2.7.egg\tornado\ioloop.py", line 519, in close
    os.close(fd)
OSError: [Errno 9] Bad file descriptor
error closing fd 664
Traceback (most recent call last):
  File "C:\Python27\lib\site-packages\tornado-3.1.1-py2.7.egg\tornado\ioloop.py", line 519, in close
    os.close(fd)
OSError: [Errno 9] Bad file descriptor
error closing fd 156
Traceback (most recent call last):
  File "C:\Python27\lib\site-packages\tornado-3.1.1-py2.7.egg\tornado\ioloop.py", line 519, in close
    os.close(fd)
OSError: [Errno 9] Bad file descriptor
F:\ccg\model\EffectModel.py modified; restarting server
error closing fd 224
Traceback (most recent call last):
  File "C:\Python27\lib\site-packages\tornado-3.1.1-py2.7.egg\tornado\ioloop.py", line 519, in close
    os.close(fd)
OSError: [Errno 9] Bad file descriptor
error closing fd 156
Traceback (most recent call last):
  File "C:\Python27\lib\site-packages\tornado-3.1.1-py2.7.egg\tornado\ioloop.py", line 519, in close
    os.close(fd)
OSError: [Errno 9] Bad file descriptor
F:\ccg\model\EffectModel.py modified; restarting server
error closing fd 224
Traceback (most recent call last):
  File "C:\Python27\lib\site-packages\tornado-3.1.1-py2.7.egg\tornado\ioloop.py", line 519, in close
    os.close(fd)
OSError: [Errno 9] Bad file descriptor
error closing fd 156
Traceback (most recent call last):
  File "C:\Python27\lib\site-packages\tornado-3.1.1-py2.7.egg\tornado\ioloop.py", line 519, in close
    os.close(fd)
OSError: [Errno 9] Bad file descriptor
mongodb error, AutoReconnect!
F:\ccg\model\EffectModel.py modified; restarting server
error closing fd 224
Traceback (most recent call last):
  File "C:\Python27\lib\site-packages\tornado-3.1.1-py2.7.egg\tornado\ioloop.py", line 519, in close
    os.close(fd)
OSError: [Errno 9] Bad file descriptor
error closing fd 156
Traceback (most recent call last):
  File "C:\Python27\lib\site-packages\tornado-3.1.1-py2.7.egg\tornado\ioloop.py", line 519, in close
    os.close(fd)
OSError: [Errno 9] Bad file descriptor
error closing fd 696
Traceback (most recent call last):
  File "C:\Python27\lib\site-packages\tornado-3.1.1-py2.7.egg\tornado\ioloop.py", line 519, in close
    os.close(fd)
OSError: [Errno 9] Bad file descriptor
error closing fd 716
Traceback (most recent call last):
  File "C:\Python27\lib\site-packages\tornado-3.1.1-py2.7.egg\tornado\ioloop.py", line 519, in close
    os.close(fd)
OSError: [Errno 9] Bad file descriptor
